<?xml version="1.0" encoding="utf-8"?>
<robot name="g1">
  <link name="gripper_base">
    <visual name="Visual">
      <geometry>
        <mesh filename="package://g1/meshes/visual/L0_visual_0.stl" scale="0.001 0.001 0.001"/>
      </geometry>
      <material name="Material">
        <color rgba="0.8 0.8 0.8 1.0"/>
      </material>
    </visual>
    <visual name="Visual">
      <geometry>
        <mesh filename="package://g1/meshes/visual/L0_visual_1.stl" scale="0.001 0.001 0.001"/>
      </geometry>
      <material name="Material">
        <color rgba="0.8 0.8 0.8 1.0"/>
      </material>
    </visual>
    <visual name="Visual">
      <geometry>
        <mesh filename="package://g1/meshes/visual/L0_visual_2.stl" scale="0.001 0.001 0.001"/>
      </geometry>
      <material name="Material">
        <color rgba="0.8 0.8 0.8 1.0"/>
      </material>
    </visual>
    <visual name="Visual">
      <geometry>
        <mesh filename="package://g1/meshes/visual/L0_visual_3.stl" scale="0.001 0.001 0.001"/>
      </geometry>
      <material name="Material">
        <color rgba="0.8 0.8 0.8 1.0"/>
      </material>
    </visual>
    <visual name="Visual">
      <geometry>
        <mesh filename="package://g1/meshes/visual/L0_visual_4.stl" scale="0.001 0.001 0.001"/>
      </geometry>
      <material name="Material">
        <color rgba="0.8 0.8 0.8 1.0"/>
      </material>
    </visual>
    <visual name="Visual">
      <geometry>
        <mesh filename="package://g1/meshes/visual/L0_visual_5.stl" scale="0.001 0.001 0.001"/>
      </geometry>
      <material name="Material">
        <color rgba="0.8 0.8 0.8 1.0"/>
      </material>
    </visual>
    <visual name="Visual">
      <geometry>
        <mesh filename="package://g1/meshes/visual/L0_visual_6.stl" scale="0.001 0.001 0.001"/>
      </geometry>
      <material name="Material">
        <color rgba="0.8 0.8 0.8 1.0"/>
      </material>
    </visual>
    <visual name="Visual">
      <geometry>
        <mesh filename="package://g1/meshes/visual/L0_visual_7.stl" scale="0.001 0.001 0.001"/>
      </geometry>
      <material name="Material">
        <color rgba="0.8 0.8 0.8 1.0"/>
      </material>
    </visual>
    <visual name="Visual">
      <geometry>
        <mesh filename="package://g1/meshes/visual/L0_visual_8.stl" scale="0.001 0.001 0.001"/>
      </geometry>
      <material name="Material">
        <color rgba="0.8 0.8 0.8 1.0"/>
      </material>
    </visual>
    <visual name="Visual">
      <geometry>
        <mesh filename="package://g1/meshes/visual/L0_visual_9.stl" scale="0.001 0.001 0.001"/>
      </geometry>
      <material name="Material">
        <color rgba="0.8 0.8 0.8 1.0"/>
      </material>
    </visual>
    <visual name="Visual">
      <geometry>
        <mesh filename="package://g1/meshes/visual/L0_visual_10.stl" scale="0.001 0.001 0.001"/>
      </geometry>
      <material name="Material">
        <color rgba="0.8 0.8 0.8 1.0"/>
      </material>
    </visual>
    <collision name="Collision">
      <geometry>
        <mesh filename="package://g1/meshes/collision/L0_collision_0.stl" scale="0.001 0.001 0.001"/>
      </geometry>
    </collision>
    <collision name="Collision">
      <geometry>
        <mesh filename="package://g1/meshes/collision/L0_collision_1.stl" scale="0.001 0.001 0.001"/>
      </geometry>
    </collision>
    <collision name="Collision">
      <geometry>
        <mesh filename="package://g1/meshes/collision/L0_collision_2.stl" scale="0.001 0.001 0.001"/>
      </geometry>
    </collision>
    <collision name="Collision">
      <geometry>
        <mesh filename="package://g1/meshes/collision/L0_collision_3.stl" scale="0.001 0.001 0.001"/>
      </geometry>
    </collision>
    <collision name="Collision">
      <geometry>
        <mesh filename="package://g1/meshes/collision/L0_collision_4.stl" scale="0.001 0.001 0.001"/>
      </geometry>
    </collision>
    <collision name="Collision">
      <geometry>
        <mesh filename="package://g1/meshes/collision/L0_collision_5.stl" scale="0.001 0.001 0.001"/>
      </geometry>
    </collision>
    <collision name="Collision">
      <geometry>
        <mesh filename="package://g1/meshes/collision/L0_collision_6.stl" scale="0.001 0.001 0.001"/>
      </geometry>
    </collision>
    <collision name="Collision">
      <geometry>
        <mesh filename="package://g1/meshes/collision/L0_collision_7.stl" scale="0.001 0.001 0.001"/>
      </geometry>
    </collision>
    <collision name="Collision">
      <geometry>
        <mesh filename="package://g1/meshes/collision/L0_collision_8.stl" scale="0.001 0.001 0.001"/>
      </geometry>
    </collision>
    <collision name="Collision">
      <geometry>
        <mesh filename="package://g1/meshes/collision/L0_collision_9.stl" scale="0.001 0.001 0.001"/>
      </geometry>
    </collision>
    <collision name="Collision">
      <geometry>
        <mesh filename="package://g1/meshes/collision/L0_collision_10.stl" scale="0.001 0.001 0.001"/>
      </geometry>
    </collision>
  </link>
  <link name="gripper_jaw_l">
    <visual name="Visual">
      <geometry>
        <mesh filename="package://g1/meshes/visual/L1_visual_0.stl" scale="0.001 0.001 0.001"/>
      </geometry>
      <material name="Material">
        <color rgba="0.8 0.8 0.8 1.0"/>
      </material>
    </visual>
    <visual name="Visual">
      <geometry>
        <mesh filename="package://g1/meshes/visual/L1_visual_1.stl" scale="0.001 0.001 0.001"/>
      </geometry>
      <material name="Material">
        <color rgba="0.8 0.8 0.8 1.0"/>
      </material>
    </visual>
    <visual name="Visual">
      <geometry>
        <mesh filename="package://g1/meshes/visual/L1_visual_2.stl" scale="0.001 0.001 0.001"/>
      </geometry>
      <material name="Material">
        <color rgba="0.8 0.8 0.8 1.0"/>
      </material>
    </visual>
    <visual name="Visual">
      <geometry>
        <mesh filename="package://g1/meshes/visual/L1_visual_3.stl" scale="0.001 0.001 0.001"/>
      </geometry>
      <material name="Material">
        <color rgba="0.8 0.8 0.8 1.0"/>
      </material>
    </visual>
    <visual name="Visual">
      <geometry>
        <mesh filename="package://g1/meshes/visual/L1_visual_4.stl" scale="0.001 0.001 0.001"/>
      </geometry>
      <material name="Material">
        <color rgba="0.8 0.8 0.8 1.0"/>
      </material>
    </visual>
    <visual name="Visual">
      <geometry>
        <mesh filename="package://g1/meshes/visual/L1_visual_5.stl" scale="0.001 0.001 0.001"/>
      </geometry>
      <material name="Material">
        <color rgba="0.8 0.8 0.8 1.0"/>
      </material>
    </visual>
    <collision name="Collision">
      <geometry>
        <mesh filename="package://g1/meshes/collision/L1_collision_0.stl" scale="0.001 0.001 0.001"/>
      </geometry>
    </collision>
    <collision name="Collision">
      <geometry>
        <mesh filename="package://g1/meshes/collision/L1_collision_1.stl" scale="0.001 0.001 0.001"/>
      </geometry>
    </collision>
    <collision name="Collision">
      <geometry>
        <mesh filename="package://g1/meshes/collision/L1_collision_2.stl" scale="0.001 0.001 0.001"/>
      </geometry>
    </collision>
    <collision name="Collision">
      <geometry>
        <mesh filename="package://g1/meshes/collision/L1_collision_3.stl" scale="0.001 0.001 0.001"/>
      </geometry>
    </collision>
    <collision name="Collision">
      <geometry>
        <mesh filename="package://g1/meshes/collision/L1_collision_4.stl" scale="0.001 0.001 0.001"/>
      </geometry>
    </collision>
    <collision name="Collision">
      <geometry>
        <mesh filename="package://g1/meshes/collision/L1_collision_5.stl" scale="0.001 0.001 0.001"/>
      </geometry>
    </collision>
  </link>
  <link name="gripper_jaw_r">
    <visual name="Visual">
      <geometry>
        <mesh filename="package://g1/meshes/visual/L2_visual_0.stl" scale="0.001 0.001 0.001"/>
      </geometry>
      <material name="Material">
        <color rgba="0.8 0.8 0.8 1.0"/>
      </material>
    </visual>
    <visual name="Visual">
      <geometry>
        <mesh filename="package://g1/meshes/visual/L2_visual_1.stl" scale="0.001 0.001 0.001"/>
      </geometry>
      <material name="Material">
        <color rgba="0.8 0.8 0.8 1.0"/>
      </material>
    </visual>
    <visual name="Visual">
      <geometry>
        <mesh filename="package://g1/meshes/visual/L2_visual_2.stl" scale="0.001 0.001 0.001"/>
      </geometry>
      <material name="Material">
        <color rgba="0.8 0.8 0.8 1.0"/>
      </material>
    </visual>
    <visual name="Visual">
      <geometry>
        <mesh filename="package://g1/meshes/visual/L2_visual_3.stl" scale="0.001 0.001 0.001"/>
      </geometry>
      <material name="Material">
        <color rgba="0.8 0.8 0.8 1.0"/>
      </material>
    </visual>
    <visual name="Visual">
      <geometry>
        <mesh filename="package://g1/meshes/visual/L2_visual_4.stl" scale="0.001 0.001 0.001"/>
      </geometry>
      <material name="Material">
        <color rgba="0.8 0.8 0.8 1.0"/>
      </material>
    </visual>
    <visual name="Visual">
      <geometry>
        <mesh filename="package://g1/meshes/visual/L2_visual_5.stl" scale="0.001 0.001 0.001"/>
      </geometry>
      <material name="Material">
        <color rgba="0.8 0.8 0.8 1.0"/>
      </material>
    </visual>
    <collision name="Collision">
      <geometry>
        <mesh filename="package://g1/meshes/collision/L2_collision_0.stl" scale="0.001 0.001 0.001"/>
      </geometry>
    </collision>
    <collision name="Collision">
      <geometry>
        <mesh filename="package://g1/meshes/collision/L2_collision_1.stl" scale="0.001 0.001 0.001"/>
      </geometry>
    </collision>
    <collision name="Collision">
      <geometry>
        <mesh filename="package://g1/meshes/collision/L2_collision_2.stl" scale="0.001 0.001 0.001"/>
      </geometry>
    </collision>
    <collision name="Collision">
      <geometry>
        <mesh filename="package://g1/meshes/collision/L2_collision_3.stl" scale="0.001 0.001 0.001"/>
      </geometry>
    </collision>
    <collision name="Collision">
      <geometry>
        <mesh filename="package://g1/meshes/collision/L2_collision_4.stl" scale="0.001 0.001 0.001"/>
      </geometry>
    </collision>
    <collision name="Collision">
      <geometry>
        <mesh filename="package://g1/meshes/collision/L2_collision_5.stl" scale="0.001 0.001 0.001"/>
      </geometry>
    </collision>
  </link>
  <joint name="joint_gripper_jaw_l" type="prismatic">
    <parent link="gripper_base"/>
    <child link="gripper_jaw_l"/>
    <axis xyz="1.0 0.0 0.0"/>
    <limit effort="0.0" lower="0.0008" upper="0.01" velocity="0.0"/>
    <origin rpy="0.0 -0.0 0.0" xyz="0.0 0.0 0.0"/>
  </joint>
  <joint name="joint_gripper_jaw_r" type="prismatic">
    <parent link="gripper_base"/>
    <child link="gripper_jaw_r"/>
    <axis xyz="-1.0 0.0 0.0"/>
    <limit effort="0.0" lower="0.0008" upper="0.01" velocity="0.0"/>
    <origin rpy="0.0 -0.0 0.0" xyz="0.0 0.0 0.0"/>
  </joint>
</robot>
